<?xml version="1.0" ?>
<robot xmlns:xacro="http://ros.org/wiki/xacro">
  <!-- <gazebo reference="joint2_link">
    <gravity>0</gravity>
  </gazebo>
  <gazebo reference="joint3_link">
    <gravity>0</gravity>
  </gazebo>
  <gazebo reference="joint4_link">
    <gravity>0</gravity>
  </gazebo>
  <gazebo reference="joint5_link">
    <gravity>0</gravity>
  </gazebo>
  <gazebo reference="laser_Link">
    <gravity>0</gravity>
  </gazebo> -->
    <!-- <link name="dummy_link"></link> -->
    <link name="world"></link>
  <link
    name="base_link">
    <inertial>
      <origin
        xyz="0.0082451 0.15 1.9295E-17"
        rpy="0 0 0" />
      <mass
        value="334.45" />
      <inertia
        ixx="32.989"
        ixy="2.8333E-16"
        ixz="-1.1027E-15"
        iyy="59.421"
        iyz="-6.6498E-17"
        izz="31.449" />
    </inertial>
    <visual>
      <origin
        xyz="0 0 0"
        rpy="0 0 0" />
      <geometry>
        <mesh
          filename="package://cyberknife/meshes/base_link.STL" />
      </geometry>
      <material
        name="">
        <color
          rgba="0.79216 0.81961 0.93333 1" />
      </material>
    </visual>
    <collision>
      <origin
        xyz="0 0 0"
        rpy="0 0 0" />
      <geometry>
        <mesh
          filename="package://cyberknife/meshes/base_link.STL" />
      </geometry>
    </collision>
  </link>
  <joint name="world_joint" type="fixed">
    <parent link="world"/>
    <child link="base_link"/>
  </joint> 
  <!-- <joint name="dummy_joint" type="fixed">
    <origin rpy="0 0 0" xyz="0 0 0" />
    <parent link="dummy_link"/>
    <child link="base_link"/>
  </joint>  -->
  <link
    name="base2_link">
    <inertial>
      <origin
        xyz="-0.021051 0.33235 -0.048325"
        rpy="0 0 0" />
      <mass
        value="663.35" />
      <inertia
        ixx="87.738"
        ixy="2.2863"
        ixz="5.6219"
        iyy="118.23"
        iyz="3.7712"
        izz="86.914" />
    </inertial>
    <visual>
      <origin
        xyz="0 0 0"
        rpy="0 0 0" />
      <geometry>
        <mesh
          filename="package://cyberknife/meshes/base2_link.STL" />
      </geometry>
      <material
        name="">
        <color
          rgba="0.79216 0.81961 0.93333 1" />
      </material>
    </visual>
    <collision>
      <origin
        xyz="0 0 0"
        rpy="0 0 0" />
      <geometry>
        <mesh
          filename="package://cyberknife/meshes/base2_link.STL" />
      </geometry>
    </collision>
  </link>
  <joint
    name="base2"
    type="continuous">
    <origin
      xyz="0 0 0.3"
      rpy="1.5708 0 0" />
    <parent
      link="base_link" />
    <child
      link="base2_link" />
    <axis
      xyz="0 1 0" />
  </joint>
  <link
    name="joint1_link">
    <inertial>
      <origin
        xyz="-5.5511E-17 0.625 0.27716"
        rpy="0 0 0" />
      <mass
        value="208.9" />
      <inertia
        ixx="49.449"
        ixy="-1.5799E-15"
        ixz="-1.808E-16"
        iyy="4.9083"
        iyz="9.1254E-17"
        izz="49.534" />
    </inertial>
    <visual>
      <origin
        xyz="0 0 0"
        rpy="0 0 0" />
      <geometry>
        <mesh
          filename="package://cyberknife/meshes/joint1_link.STL" />
      </geometry>
      <material
        name="">
        <color
          rgba="0.79216 0.81961 0.93333 1" />
      </material>
    </visual>
    <collision>
      <origin
        xyz="0 0 0"
        rpy="0 0 0" />
      <geometry>
        <mesh
          filename="package://cyberknife/meshes/joint1_link.STL" />
      </geometry>
    </collision>
  </link>
  <joint
    name="joint1"
    type="revolute">
    <origin
      xyz="0.35 0.45 0"
      rpy="0 0 0" />
    <parent
      link="base2_link" />
    <child
      link="joint1_link" />
    <axis
      xyz="0 0 1" />
    <limit
      lower="-1.57"
      upper="0.8"
      effort="0"
      velocity="0" />
  </joint>
  <link
    name="joint2_link">
    <inertial>
      <origin
        xyz="0.043481 0 -0.0038586"
        rpy="0 0 0" />
      <mass
        value="206.09" />
      <inertia
        ixx="6.8504"
        ixy="4.4181E-15"
        ixz="-0.034577"
        iyy="36.431"
        iyz="-3.0254E-16"
        izz="40.324" />
    </inertial>
    <visual>
      <origin
        xyz="0 0 0"
        rpy="0 0 0" />
      <geometry>
        <mesh
          filename="package://cyberknife/meshes/joint2_link.STL" />
      </geometry>
      <material
        name="">
        <color
          rgba="0.79216 0.81961 0.93333 1" />
      </material>
    </visual>
    <collision>
      <origin
        xyz="0 0 0"
        rpy="0 0 0" />
      <geometry>
        <mesh
          filename="package://cyberknife/meshes/joint2_link.STL" />
      </geometry>
    </collision>
</link>
  <joint
    name="joint2"
    type="revolute">
    <origin
      xyz="0 1.25 0"
      rpy="0 0 0" />
    <parent
      link="joint1_link" />
    <child
      link="joint2_link" />
    <axis
      xyz="0 0 1" />
    <limit
      lower="-0.97"
      upper="4.015"
      effort="0"
      velocity="0" />
  </joint>
  <link
    name="joint3_link">
    <inertial>
      <origin
        xyz="0.14843 7.5699E-07 -6.3398E-08"
        rpy="0 0 0" />
      <mass
        value="9.8998" />
      <inertia
        ixx="0.055624"
        ixy="-2.1955E-09"
        ixz="1.531E-17"
        iyy="0.095588"
        iyz="-2.1355E-06"
        izz="0.092129" />
    </inertial>
    <visual>
      <origin
        xyz="0 0 0"
        rpy="0 0 0" />
      <geometry>
        <mesh
          filename="package://cyberknife/meshes/joint3_link.STL" />
      </geometry>
      <material
        name="">
        <color
          rgba="0.79216 0.81961 0.93333 1" />
      </material>
    </visual>
    <collision>
      <origin
        xyz="0 0 0"
        rpy="0 0 0" />
      <geometry>
        <mesh
          filename="package://cyberknife/meshes/joint3_link.STL" />
      </geometry>
    </collision>
</link>
  <joint
    name="joint3"
    type="continuous">
    <origin
      xyz="0.9 0 0"
      rpy="0 0 0" />
    <parent
      link="joint2_link" />
    <child
      link="joint3_link" />
    <axis
      xyz="1 0 0" />
  </joint>
  <link
    name="joint4_link">
    <inertial>
      <origin
        xyz="0.063752 -2.2204E-16 4.9549E-18"
        rpy="0 0 0" />
      <mass
        value="5.4704" />
      <inertia
        ixx="0.07183"
        ixy="5.456E-18"
        ixz="1.2367E-18"
        iyy="0.10401"
        iyz="-2.1337E-18"
        izz="0.051502" />
    </inertial>
    <visual>
      <origin
        xyz="0 0 0"
        rpy="0 0 0" />
      <geometry>
        <mesh
          filename="package://cyberknife/meshes/joint4_link.STL" />
      </geometry>
      <material
        name="">
        <color
          rgba="0.79216 0.81961 0.93333 1" />
      </material>
    </visual>
    <collision>
      <origin
        xyz="0 0 0"
        rpy="0 0 0" />
      <geometry>
        <mesh
          filename="package://cyberknife/meshes/joint4_link.STL" />
      </geometry>
    </collision>
</link>
  <joint
    name="joint4"
    type="revolute">
    <origin
      xyz="0.2 0 0"
      rpy="0 0 0" />
    <parent
      link="joint3_link" />
    <child
      link="joint4_link" />
    <axis
      xyz="0 0 1" />
    <limit
      lower="-1.55"
      upper="1.55"
      effort="0"
      velocity="0" />
  </joint>
  <link
    name="joint5_link">
    <inertial>
      <origin
        xyz="0.1006 0.060159 -7.521E-09"
        rpy="0 0 0" />
      <mass
        value="65.816" />
      <inertia
        ixx="5.3463"
        ixy="0.0023624"
        ixz="5.5471E-07"
        iyy="0.95763"
        iyz="-3.2254E-08"
        izz="4.8226" />
    </inertial>
    <visual>
      <origin
        xyz="0 0 0"
        rpy="0 0 0" />
      <geometry>
        <mesh
          filename="package://cyberknife/meshes/joint5_link.STL" />
      </geometry>
      <material
        name="">
        <color
          rgba="0.79216 0.81961 0.93333 1" />
      </material>
    </visual>
    <collision>
      <origin
        xyz="0 0 0"
        rpy="0 0 0" />
      <geometry>
        <mesh
          filename="package://cyberknife/meshes/joint5_link.STL" />
      </geometry>
    </collision>
</link>
  <joint
    name="joint5"
    type="continuous">
    <origin
      xyz="0.15 0 0"
      rpy="0 0 0" />
    <parent
      link="joint4_link" />
    <child
      link="joint5_link" />
    <axis
      xyz="1 0 0" />
  </joint>
  <link
    name="laser_Link">
    <inertial>
      <origin
        xyz="0.0005 -0.495 0.0005"
        rpy="0 0 0" />
      <mass
        value="0.00099" />
      <inertia
        ixx="8.0858E-05"
        ixy="-3.5293E-24"
        ixz="-6.8932E-27"
        iyy="1.65E-10"
        iyz="-6.8242E-24"
        izz="8.0858E-05" />
    </inertial>
    <visual>
      <origin
        xyz="0 0 0"
        rpy="0 0 0" />
      <geometry>
        <mesh
          filename="package://cyberknife/meshes/laser_Link.STL" />
      </geometry>
      <material
        name="">
        <color
          rgba="0.79216 0.81961 0.93333 1" />
      </material>
    </visual>
    <collision>
      <origin
        xyz="0 0 0"
        rpy="0 0 0" />
      <geometry>
        <mesh
          filename="package://cyberknife/meshes/laser_Link.STL" />
      </geometry>
    </collision>
  </link>
  <!-- <joint
    name="laser"
    type="prismatic">
    <origin
      xyz="0.1 0.063578 0"
      rpy="0 0 0" />
    <parent
      link="joint5_Link" />
    <child
      link="laser_Link" />
    <axis
      xyz="0 1 0" />
    <limit
      lower="-0.5"
      upper="0.5"
      effort="0"
      velocity="0" />
  </joint> -->
  <joint
    name="laser"
    type="revolute">
    <origin
      xyz="0.1 -0.5 0"
      rpy="0 0 0" />
    <parent
      link="joint5_link" />
    <child
      link="laser_Link" />
    <axis
      xyz="0 1 0" />
    <limit
      lower="0"
      upper="0"
      effort="0"
      velocity="0" />
  </joint>
</robot>